[2024-03-01 20:16:19,935: WARNING/MainProcess] /usr/local/lib/python3.12/site-packages/celery/worker/consumer/consumer.py:507: CPendingDeprecationWarning: The broker_connection_retry configuration setting will no longer determine
whether broker connection retries are made during startup in Celery 6.0 and above.
If you wish to retain the existing behavior for retrying connections on startup,
you should set broker_connection_retry_on_startup to True.
  warnings.warn(

[2024-03-01 20:16:20,008: INFO/MainProcess] Connected to redis://redis:6379/0
[2024-03-01 20:16:20,015: WARNING/MainProcess] /usr/local/lib/python3.12/site-packages/celery/worker/consumer/consumer.py:507: CPendingDeprecationWarning: The broker_connection_retry configuration setting will no longer determine
whether broker connection retries are made during startup in Celery 6.0 and above.
If you wish to retain the existing behavior for retrying connections on startup,
you should set broker_connection_retry_on_startup to True.
  warnings.warn(

[2024-03-01 20:16:20,023: INFO/MainProcess] mingle: searching for neighbors
[2024-03-01 20:16:21,064: INFO/MainProcess] mingle: all alone
[2024-03-01 20:16:21,180: INFO/MainProcess] celery@ad0d6672afee ready.
[2024-03-01 20:29:01,605: WARNING/MainProcess] /usr/local/lib/python3.12/site-packages/celery/worker/consumer/consumer.py:507: CPendingDeprecationWarning: The broker_connection_retry configuration setting will no longer determine
whether broker connection retries are made during startup in Celery 6.0 and above.
If you wish to retain the existing behavior for retrying connections on startup,
you should set broker_connection_retry_on_startup to True.
  warnings.warn(

[2024-03-01 20:29:01,792: INFO/MainProcess] Connected to redis://redis:6379/0
[2024-03-01 20:29:01,803: WARNING/MainProcess] /usr/local/lib/python3.12/site-packages/celery/worker/consumer/consumer.py:507: CPendingDeprecationWarning: The broker_connection_retry configuration setting will no longer determine
whether broker connection retries are made during startup in Celery 6.0 and above.
If you wish to retain the existing behavior for retrying connections on startup,
you should set broker_connection_retry_on_startup to True.
  warnings.warn(

[2024-03-01 20:29:01,822: INFO/MainProcess] mingle: searching for neighbors
[2024-03-01 20:29:02,899: INFO/MainProcess] mingle: all alone
[2024-03-01 20:29:03,004: INFO/MainProcess] celery@9d9acda21fe4 ready.
[2024-03-01 20:32:25,944: WARNING/MainProcess] /usr/local/lib/python3.12/site-packages/celery/worker/consumer/consumer.py:507: CPendingDeprecationWarning: The broker_connection_retry configuration setting will no longer determine
whether broker connection retries are made during startup in Celery 6.0 and above.
If you wish to retain the existing behavior for retrying connections on startup,
you should set broker_connection_retry_on_startup to True.
  warnings.warn(

[2024-03-01 20:32:26,050: INFO/MainProcess] Connected to redis://redis:6379/0
[2024-03-01 20:32:26,060: WARNING/MainProcess] /usr/local/lib/python3.12/site-packages/celery/worker/consumer/consumer.py:507: CPendingDeprecationWarning: The broker_connection_retry configuration setting will no longer determine
whether broker connection retries are made during startup in Celery 6.0 and above.
If you wish to retain the existing behavior for retrying connections on startup,
you should set broker_connection_retry_on_startup to True.
  warnings.warn(

[2024-03-01 20:32:26,068: INFO/MainProcess] mingle: searching for neighbors
[2024-03-01 20:32:27,109: INFO/MainProcess] mingle: all alone
[2024-03-01 20:32:27,222: INFO/MainProcess] celery@64bec30ed021 ready.
[2024-03-01 20:36:25,458: WARNING/MainProcess] /usr/local/lib/python3.12/site-packages/celery/worker/consumer/consumer.py:507: CPendingDeprecationWarning: The broker_connection_retry configuration setting will no longer determine
whether broker connection retries are made during startup in Celery 6.0 and above.
If you wish to retain the existing behavior for retrying connections on startup,
you should set broker_connection_retry_on_startup to True.
  warnings.warn(

[2024-03-01 20:36:25,622: INFO/MainProcess] Connected to redis://redis:6379/0
[2024-03-01 20:36:25,643: WARNING/MainProcess] /usr/local/lib/python3.12/site-packages/celery/worker/consumer/consumer.py:507: CPendingDeprecationWarning: The broker_connection_retry configuration setting will no longer determine
whether broker connection retries are made during startup in Celery 6.0 and above.
If you wish to retain the existing behavior for retrying connections on startup,
you should set broker_connection_retry_on_startup to True.
  warnings.warn(

[2024-03-01 20:36:25,665: INFO/MainProcess] mingle: searching for neighbors
[2024-03-01 20:36:26,758: INFO/MainProcess] mingle: all alone
[2024-03-01 20:36:26,859: INFO/MainProcess] celery@bb255e926951 ready.
[2024-03-01 20:45:43,770: INFO/MainProcess] Task women.tasks.send_contact_email_message_task[388d458d-46fc-455e-8916-52fd2fbb13bf] received
[2024-03-01 20:54:52,262: WARNING/MainProcess] /usr/local/lib/python3.12/site-packages/celery/worker/consumer/consumer.py:507: CPendingDeprecationWarning: The broker_connection_retry configuration setting will no longer determine
whether broker connection retries are made during startup in Celery 6.0 and above.
If you wish to retain the existing behavior for retrying connections on startup,
you should set broker_connection_retry_on_startup to True.
  warnings.warn(

[2024-03-01 20:54:52,475: INFO/MainProcess] Connected to redis://redis:6379/0
[2024-03-01 20:54:52,480: WARNING/MainProcess] /usr/local/lib/python3.12/site-packages/celery/worker/consumer/consumer.py:507: CPendingDeprecationWarning: The broker_connection_retry configuration setting will no longer determine
whether broker connection retries are made during startup in Celery 6.0 and above.
If you wish to retain the existing behavior for retrying connections on startup,
you should set broker_connection_retry_on_startup to True.
  warnings.warn(

[2024-03-01 20:54:52,489: INFO/MainProcess] mingle: searching for neighbors
[2024-03-01 20:54:53,521: INFO/MainProcess] mingle: all alone
[2024-03-01 20:54:53,623: INFO/MainProcess] celery@993ae5257830 ready.
[2024-03-01 21:45:39,763: WARNING/MainProcess] /usr/local/lib/python3.12/site-packages/celery/worker/consumer/consumer.py:507: CPendingDeprecationWarning: The broker_connection_retry configuration setting will no longer determine
whether broker connection retries are made during startup in Celery 6.0 and above.
If you wish to retain the existing behavior for retrying connections on startup,
you should set broker_connection_retry_on_startup to True.
  warnings.warn(

[2024-03-01 21:45:39,832: INFO/MainProcess] Connected to redis://redis:6379/0
[2024-03-01 21:45:39,836: WARNING/MainProcess] /usr/local/lib/python3.12/site-packages/celery/worker/consumer/consumer.py:507: CPendingDeprecationWarning: The broker_connection_retry configuration setting will no longer determine
whether broker connection retries are made during startup in Celery 6.0 and above.
If you wish to retain the existing behavior for retrying connections on startup,
you should set broker_connection_retry_on_startup to True.
  warnings.warn(

[2024-03-01 21:45:39,851: INFO/MainProcess] mingle: searching for neighbors
[2024-03-01 21:45:40,884: INFO/MainProcess] mingle: all alone
[2024-03-01 21:45:40,998: INFO/MainProcess] celery@a27fc75fa9f2 ready.
[2024-03-01 21:51:16,970: WARNING/MainProcess] /usr/local/lib/python3.12/site-packages/celery/worker/consumer/consumer.py:507: CPendingDeprecationWarning: The broker_connection_retry configuration setting will no longer determine
whether broker connection retries are made during startup in Celery 6.0 and above.
If you wish to retain the existing behavior for retrying connections on startup,
you should set broker_connection_retry_on_startup to True.
  warnings.warn(

[2024-03-01 21:51:17,022: INFO/MainProcess] Connected to redis://redis:6379/0
[2024-03-01 21:51:17,026: WARNING/MainProcess] /usr/local/lib/python3.12/site-packages/celery/worker/consumer/consumer.py:507: CPendingDeprecationWarning: The broker_connection_retry configuration setting will no longer determine
whether broker connection retries are made during startup in Celery 6.0 and above.
If you wish to retain the existing behavior for retrying connections on startup,
you should set broker_connection_retry_on_startup to True.
  warnings.warn(

[2024-03-01 21:51:17,033: INFO/MainProcess] mingle: searching for neighbors
[2024-03-01 21:51:18,056: INFO/MainProcess] mingle: all alone
[2024-03-01 21:51:18,094: INFO/MainProcess] celery@a27fc75fa9f2 ready.
[2024-03-01 21:58:54,343: INFO/MainProcess] Task women.tasks.send_contact_email_message_task[78e1df72-e37a-404b-9258-9c1d51f464f2] received
[2024-03-01 22:00:52,393: ERROR/ForkPoolWorker-7] Task women.tasks.send_contact_email_message_task[78e1df72-e37a-404b-9258-9c1d51f464f2] raised unexpected: SMTPServerDisconnected('Connection unexpectedly closed')
Traceback (most recent call last):
  File "/usr/local/lib/python3.12/site-packages/celery/app/trace.py", line 477, in trace_task
    R = retval = fun(*args, **kwargs)
                 ^^^^^^^^^^^^^^^^^^^^
  File "/usr/local/lib/python3.12/site-packages/celery/app/trace.py", line 760, in __protected_call__
    return self.run(*args, **kwargs)
           ^^^^^^^^^^^^^^^^^^^^^^^^^
  File "/app/women/tasks.py", line 22, in send_contact_email_message_task
    return send_contact_email_message(subject, email, content, ip, user_id)
           ^^^^^^^^^^^^^^^^^^^^^^^^^^^^^^^^^^^^^^^^^^^^^^^^^^^^^^^^^^^^^^^^
  File "/app/women/email.py", line 22, in send_contact_email_message
    email.send(fail_silently=False)
  File "/usr/local/lib/python3.12/site-packages/django/core/mail/message.py", line 298, in send
    return self.get_connection(fail_silently).send_messages([self])
           ^^^^^^^^^^^^^^^^^^^^^^^^^^^^^^^^^^^^^^^^^^^^^^^^^^^^^^^^
  File "/usr/local/lib/python3.12/site-packages/django/core/mail/backends/smtp.py", line 127, in send_messages
    new_conn_created = self.open()
                       ^^^^^^^^^^^
  File "/usr/local/lib/python3.12/site-packages/django/core/mail/backends/smtp.py", line 85, in open
    self.connection = self.connection_class(
                      ^^^^^^^^^^^^^^^^^^^^^^
  File "/usr/local/lib/python3.12/smtplib.py", line 255, in __init__
    (code, msg) = self.connect(host, port)
                  ^^^^^^^^^^^^^^^^^^^^^^^^
  File "/usr/local/lib/python3.12/smtplib.py", line 343, in connect
    (code, msg) = self.getreply()
                  ^^^^^^^^^^^^^^^
  File "/usr/local/lib/python3.12/smtplib.py", line 405, in getreply
    raise SMTPServerDisconnected("Connection unexpectedly closed")
smtplib.SMTPServerDisconnected: Connection unexpectedly closed
[2024-03-01 22:06:44,472: INFO/MainProcess] Task women.tasks.send_contact_email_message_task[52f0be49-1dce-42eb-8d68-622f246206a5] received
[2024-03-01 22:17:50,579: INFO/MainProcess] Task women.tasks.send_contact_email_message_task[74ec0a00-5eb7-45cf-8dd4-499f03498632] received
[2024-03-01 22:23:20,534: INFO/MainProcess] Task women.tasks.send_activate_email_message_task[fcfd67e8-95c2-491e-b4fd-d420ac0e3c04] received
[2024-03-01 22:26:24,894: INFO/MainProcess] Task women.tasks.send_contact_email_message_task[c030b7a0-4b87-4822-a4cc-9afe7a20a44e] received
[2024-03-01 22:29:09,431: INFO/MainProcess] Task women.tasks.send_contact_email_message_task[a0e8fe39-efdd-41ce-bfa3-6fe26a25e132] received
[2024-03-01 22:31:58,330: INFO/MainProcess] Task women.tasks.send_contact_email_message_task[6d170dae-96ae-4587-ac64-e59ecbcfbbe3] received
[2024-03-01 22:36:44,504: ERROR/MainProcess] Task handler raised error: TimeLimitExceeded(1800)
Traceback (most recent call last):
  File "/usr/local/lib/python3.12/site-packages/billiard/pool.py", line 683, in on_hard_timeout
    raise TimeLimitExceeded(job._timeout)
billiard.einfo.ExceptionWithTraceback: 
"""
Traceback (most recent call last):
  File "/usr/local/lib/python3.12/site-packages/billiard/pool.py", line 683, in on_hard_timeout
    raise TimeLimitExceeded(job._timeout)
billiard.exceptions.TimeLimitExceeded: TimeLimitExceeded(1800,)
"""
[2024-03-01 22:36:44,513: ERROR/MainProcess] Hard time limit (1800s) exceeded for women.tasks.send_contact_email_message_task[52f0be49-1dce-42eb-8d68-622f246206a5]
[2024-03-01 22:36:44,637: ERROR/MainProcess] Process 'ForkPoolWorker-7' pid:14 exited with 'signal 9 (SIGKILL)'
[2024-03-01 22:44:21,492: WARNING/MainProcess] /usr/local/lib/python3.12/site-packages/celery/worker/consumer/consumer.py:507: CPendingDeprecationWarning: The broker_connection_retry configuration setting will no longer determine
whether broker connection retries are made during startup in Celery 6.0 and above.
If you wish to retain the existing behavior for retrying connections on startup,
you should set broker_connection_retry_on_startup to True.
  warnings.warn(

[2024-03-01 22:44:22,342: INFO/MainProcess] Connected to redis://redis:6379/0
[2024-03-01 22:44:22,346: WARNING/MainProcess] /usr/local/lib/python3.12/site-packages/celery/worker/consumer/consumer.py:507: CPendingDeprecationWarning: The broker_connection_retry configuration setting will no longer determine
whether broker connection retries are made during startup in Celery 6.0 and above.
If you wish to retain the existing behavior for retrying connections on startup,
you should set broker_connection_retry_on_startup to True.
  warnings.warn(

[2024-03-01 22:44:22,359: INFO/MainProcess] mingle: searching for neighbors
[2024-03-01 22:44:23,384: INFO/MainProcess] mingle: all alone
[2024-03-01 22:44:23,422: INFO/MainProcess] celery@2ea43ac5311b ready.
[2024-03-01 22:48:16,867: WARNING/MainProcess] /usr/local/lib/python3.12/site-packages/celery/worker/consumer/consumer.py:507: CPendingDeprecationWarning: The broker_connection_retry configuration setting will no longer determine
whether broker connection retries are made during startup in Celery 6.0 and above.
If you wish to retain the existing behavior for retrying connections on startup,
you should set broker_connection_retry_on_startup to True.
  warnings.warn(

[2024-03-01 22:48:16,930: INFO/MainProcess] Connected to redis://redis:6379/0
[2024-03-01 22:48:16,936: WARNING/MainProcess] /usr/local/lib/python3.12/site-packages/celery/worker/consumer/consumer.py:507: CPendingDeprecationWarning: The broker_connection_retry configuration setting will no longer determine
whether broker connection retries are made during startup in Celery 6.0 and above.
If you wish to retain the existing behavior for retrying connections on startup,
you should set broker_connection_retry_on_startup to True.
  warnings.warn(

[2024-03-01 22:48:16,953: INFO/MainProcess] mingle: searching for neighbors
[2024-03-01 22:48:17,980: INFO/MainProcess] mingle: all alone
[2024-03-01 22:48:18,018: INFO/MainProcess] celery@d274360e2147 ready.
[2024-03-01 22:49:08,730: INFO/MainProcess] Task women.tasks.send_contact_email_message_task[b7c2d7ba-0856-4830-b1cd-be0219541b7f] received
[2024-03-01 22:49:11,675: INFO/ForkPoolWorker-7] Task women.tasks.send_contact_email_message_task[b7c2d7ba-0856-4830-b1cd-be0219541b7f] succeeded in 2.936898337000457s: None
[2024-03-02 17:05:46,599: WARNING/MainProcess] /usr/local/lib/python3.12/site-packages/celery/worker/consumer/consumer.py:507: CPendingDeprecationWarning: The broker_connection_retry configuration setting will no longer determine
whether broker connection retries are made during startup in Celery 6.0 and above.
If you wish to retain the existing behavior for retrying connections on startup,
you should set broker_connection_retry_on_startup to True.
  warnings.warn(

[2024-03-02 17:05:51,634: ERROR/MainProcess] consumer: Cannot connect to redis://redis:6379/0: Error -3 connecting to redis:6379. Try again..
Trying again in 2.00 seconds... (1/100)

[2024-03-02 17:05:58,642: ERROR/MainProcess] consumer: Cannot connect to redis://redis:6379/0: Error -3 connecting to redis:6379. Try again..
Trying again in 4.00 seconds... (2/100)

[2024-03-02 17:06:07,651: ERROR/MainProcess] consumer: Cannot connect to redis://redis:6379/0: Error -3 connecting to redis:6379. Try again..
Trying again in 6.00 seconds... (3/100)

[2024-03-02 17:06:46,893: WARNING/MainProcess] /usr/local/lib/python3.12/site-packages/celery/worker/consumer/consumer.py:507: CPendingDeprecationWarning: The broker_connection_retry configuration setting will no longer determine
whether broker connection retries are made during startup in Celery 6.0 and above.
If you wish to retain the existing behavior for retrying connections on startup,
you should set broker_connection_retry_on_startup to True.
  warnings.warn(

[2024-03-02 17:06:46,937: INFO/MainProcess] Connected to redis://redis:6379/0
[2024-03-02 17:06:46,940: WARNING/MainProcess] /usr/local/lib/python3.12/site-packages/celery/worker/consumer/consumer.py:507: CPendingDeprecationWarning: The broker_connection_retry configuration setting will no longer determine
whether broker connection retries are made during startup in Celery 6.0 and above.
If you wish to retain the existing behavior for retrying connections on startup,
you should set broker_connection_retry_on_startup to True.
  warnings.warn(

[2024-03-02 17:06:46,946: INFO/MainProcess] mingle: searching for neighbors
[2024-03-02 17:06:47,967: INFO/MainProcess] mingle: all alone
[2024-03-02 17:06:48,016: INFO/MainProcess] celery@d274360e2147 ready.
[2024-03-02 17:06:48,036: INFO/MainProcess] Task women.tasks.dbackup_task[8da824cf-74c9-4104-98af-c856358a0b82] received
[2024-03-02 17:06:48,253: WARNING/ForkPoolWorker-7] Waiting for database dump...
[2024-03-02 17:06:49,144: WARNING/ForkPoolWorker-7] Database successfully backed up
[2024-03-02 17:06:49,148: INFO/ForkPoolWorker-7] Task women.tasks.dbackup_task[8da824cf-74c9-4104-98af-c856358a0b82] succeeded in 1.107541542000007s: None
[2024-03-03 15:28:13,415: WARNING/MainProcess] /usr/local/lib/python3.12/site-packages/celery/worker/consumer/consumer.py:507: CPendingDeprecationWarning: The broker_connection_retry configuration setting will no longer determine
whether broker connection retries are made during startup in Celery 6.0 and above.
If you wish to retain the existing behavior for retrying connections on startup,
you should set broker_connection_retry_on_startup to True.
  warnings.warn(

[2024-03-03 15:28:13,526: INFO/MainProcess] Connected to redis://redis:6379/0
[2024-03-03 15:28:13,531: WARNING/MainProcess] /usr/local/lib/python3.12/site-packages/celery/worker/consumer/consumer.py:507: CPendingDeprecationWarning: The broker_connection_retry configuration setting will no longer determine
whether broker connection retries are made during startup in Celery 6.0 and above.
If you wish to retain the existing behavior for retrying connections on startup,
you should set broker_connection_retry_on_startup to True.
  warnings.warn(

[2024-03-03 15:28:13,539: INFO/MainProcess] mingle: searching for neighbors
[2024-03-03 15:28:14,578: INFO/MainProcess] mingle: all alone
[2024-03-03 15:28:14,634: INFO/MainProcess] celery@d274360e2147 ready.
[2024-03-03 15:28:14,645: INFO/MainProcess] Task women.tasks.dbackup_task[7b772e9f-d4f7-4b2b-8961-6b1a97cd4add] received
[2024-03-03 15:28:14,960: WARNING/ForkPoolWorker-7] Waiting for database dump...
[2024-03-03 15:28:16,242: WARNING/ForkPoolWorker-7] Database successfully backed up
[2024-03-03 15:28:16,248: INFO/ForkPoolWorker-7] Task women.tasks.dbackup_task[7b772e9f-d4f7-4b2b-8961-6b1a97cd4add] succeeded in 1.598629822999996s: None
[2024-03-03 15:35:37,263: WARNING/MainProcess] /usr/local/lib/python3.12/site-packages/celery/worker/consumer/consumer.py:507: CPendingDeprecationWarning: The broker_connection_retry configuration setting will no longer determine
whether broker connection retries are made during startup in Celery 6.0 and above.
If you wish to retain the existing behavior for retrying connections on startup,
you should set broker_connection_retry_on_startup to True.
  warnings.warn(

[2024-03-03 15:35:37,336: INFO/MainProcess] Connected to redis://redis:6379/0
[2024-03-03 15:35:37,340: WARNING/MainProcess] /usr/local/lib/python3.12/site-packages/celery/worker/consumer/consumer.py:507: CPendingDeprecationWarning: The broker_connection_retry configuration setting will no longer determine
whether broker connection retries are made during startup in Celery 6.0 and above.
If you wish to retain the existing behavior for retrying connections on startup,
you should set broker_connection_retry_on_startup to True.
  warnings.warn(

[2024-03-03 15:35:37,347: INFO/MainProcess] mingle: searching for neighbors
[2024-03-03 15:35:38,380: INFO/MainProcess] mingle: all alone
[2024-03-03 15:35:38,425: INFO/MainProcess] celery@d274360e2147 ready.
[2024-03-03 15:48:10,661: WARNING/MainProcess] /usr/local/lib/python3.12/site-packages/celery/worker/consumer/consumer.py:507: CPendingDeprecationWarning: The broker_connection_retry configuration setting will no longer determine
whether broker connection retries are made during startup in Celery 6.0 and above.
If you wish to retain the existing behavior for retrying connections on startup,
you should set broker_connection_retry_on_startup to True.
  warnings.warn(

[2024-03-03 15:48:10,748: INFO/MainProcess] Connected to redis://redis:6379/0
[2024-03-03 15:48:10,753: WARNING/MainProcess] /usr/local/lib/python3.12/site-packages/celery/worker/consumer/consumer.py:507: CPendingDeprecationWarning: The broker_connection_retry configuration setting will no longer determine
whether broker connection retries are made during startup in Celery 6.0 and above.
If you wish to retain the existing behavior for retrying connections on startup,
you should set broker_connection_retry_on_startup to True.
  warnings.warn(

[2024-03-03 15:48:10,780: INFO/MainProcess] mingle: searching for neighbors
[2024-03-03 15:48:11,838: INFO/MainProcess] mingle: all alone
[2024-03-03 15:48:11,891: INFO/MainProcess] celery@d274360e2147 ready.
[2024-03-06 22:27:54,279: WARNING/MainProcess] /usr/local/lib/python3.12/site-packages/celery/worker/consumer/consumer.py:507: CPendingDeprecationWarning: The broker_connection_retry configuration setting will no longer determine
whether broker connection retries are made during startup in Celery 6.0 and above.
If you wish to retain the existing behavior for retrying connections on startup,
you should set broker_connection_retry_on_startup to True.
  warnings.warn(

[2024-03-06 22:28:00,790: INFO/MainProcess] Connected to redis://redis:6379/0
[2024-03-06 22:28:00,811: WARNING/MainProcess] /usr/local/lib/python3.12/site-packages/celery/worker/consumer/consumer.py:507: CPendingDeprecationWarning: The broker_connection_retry configuration setting will no longer determine
whether broker connection retries are made during startup in Celery 6.0 and above.
If you wish to retain the existing behavior for retrying connections on startup,
you should set broker_connection_retry_on_startup to True.
  warnings.warn(

[2024-03-06 22:28:00,833: INFO/MainProcess] mingle: searching for neighbors
[2024-03-06 22:28:01,905: INFO/MainProcess] mingle: all alone
[2024-03-06 22:28:02,007: INFO/MainProcess] celery@88b3bad385fe ready.
[2024-03-06 22:28:02,041: INFO/MainProcess] Task women.tasks.dbackup_task[46fe3d7c-eada-44df-b4ac-24dbc4cea30e] received
[2024-03-06 22:28:02,762: WARNING/ForkPoolWorker-7] Waiting for database dump...
[2024-03-06 22:28:05,821: WARNING/ForkPoolWorker-7] Database successfully backed up
[2024-03-06 22:28:05,828: INFO/ForkPoolWorker-7] Task women.tasks.dbackup_task[46fe3d7c-eada-44df-b4ac-24dbc4cea30e] succeeded in 3.7782889060000002s: None
[2024-03-13 18:44:06,161: WARNING/MainProcess] /usr/local/lib/python3.12/site-packages/celery/worker/consumer/consumer.py:507: CPendingDeprecationWarning: The broker_connection_retry configuration setting will no longer determine
whether broker connection retries are made during startup in Celery 6.0 and above.
If you wish to retain the existing behavior for retrying connections on startup,
you should set broker_connection_retry_on_startup to True.
  warnings.warn(

[2024-03-13 18:44:32,144: WARNING/MainProcess] /usr/local/lib/python3.12/site-packages/celery/worker/consumer/consumer.py:507: CPendingDeprecationWarning: The broker_connection_retry configuration setting will no longer determine
whether broker connection retries are made during startup in Celery 6.0 and above.
If you wish to retain the existing behavior for retrying connections on startup,
you should set broker_connection_retry_on_startup to True.
  warnings.warn(

[2024-03-13 18:44:32,193: INFO/MainProcess] Connected to redis://redis:6379/0
[2024-03-13 18:44:32,197: WARNING/MainProcess] /usr/local/lib/python3.12/site-packages/celery/worker/consumer/consumer.py:507: CPendingDeprecationWarning: The broker_connection_retry configuration setting will no longer determine
whether broker connection retries are made during startup in Celery 6.0 and above.
If you wish to retain the existing behavior for retrying connections on startup,
you should set broker_connection_retry_on_startup to True.
  warnings.warn(

[2024-03-13 18:44:32,204: INFO/MainProcess] mingle: searching for neighbors
[2024-03-13 18:44:33,228: INFO/MainProcess] mingle: all alone
[2024-03-13 18:44:33,265: INFO/MainProcess] celery@88b3bad385fe ready.
[2024-03-13 18:44:33,274: INFO/MainProcess] Task women.tasks.dbackup_task[ae72b2a9-8efa-46eb-a799-40e893024ad4] received
[2024-03-13 18:44:33,466: WARNING/ForkPoolWorker-7] Waiting for database dump...
[2024-03-13 18:44:34,244: WARNING/ForkPoolWorker-7] Database successfully backed up
[2024-03-13 18:44:34,248: INFO/ForkPoolWorker-7] Task women.tasks.dbackup_task[ae72b2a9-8efa-46eb-a799-40e893024ad4] succeeded in 0.970420365999999s: None
[2024-03-16 19:49:57,205: WARNING/MainProcess] /usr/local/lib/python3.12/site-packages/celery/worker/consumer/consumer.py:507: CPendingDeprecationWarning: The broker_connection_retry configuration setting will no longer determine
whether broker connection retries are made during startup in Celery 6.0 and above.
If you wish to retain the existing behavior for retrying connections on startup,
you should set broker_connection_retry_on_startup to True.
  warnings.warn(

[2024-03-16 19:50:02,247: ERROR/MainProcess] consumer: Cannot connect to redis://redis:6379/0: Error -3 connecting to redis:6379. Try again..
Trying again in 2.00 seconds... (1/100)

[2024-03-16 19:50:21,267: WARNING/MainProcess] /usr/local/lib/python3.12/site-packages/celery/worker/consumer/consumer.py:507: CPendingDeprecationWarning: The broker_connection_retry configuration setting will no longer determine
whether broker connection retries are made during startup in Celery 6.0 and above.
If you wish to retain the existing behavior for retrying connections on startup,
you should set broker_connection_retry_on_startup to True.
  warnings.warn(

[2024-03-16 19:50:21,319: INFO/MainProcess] Connected to redis://redis:6379/0
[2024-03-16 19:50:21,323: WARNING/MainProcess] /usr/local/lib/python3.12/site-packages/celery/worker/consumer/consumer.py:507: CPendingDeprecationWarning: The broker_connection_retry configuration setting will no longer determine
whether broker connection retries are made during startup in Celery 6.0 and above.
If you wish to retain the existing behavior for retrying connections on startup,
you should set broker_connection_retry_on_startup to True.
  warnings.warn(

[2024-03-16 19:50:21,335: INFO/MainProcess] mingle: searching for neighbors
[2024-03-16 19:50:22,357: INFO/MainProcess] mingle: all alone
[2024-03-16 19:50:22,387: INFO/MainProcess] celery@88b3bad385fe ready.
[2024-03-16 19:50:22,396: INFO/MainProcess] Task women.tasks.dbackup_task[634b65cc-9221-4edc-944b-5a011a2f2a3d] received
[2024-03-16 19:50:22,583: WARNING/ForkPoolWorker-7] Waiting for database dump...
[2024-03-16 19:50:23,434: WARNING/ForkPoolWorker-7] Database successfully backed up
[2024-03-16 19:50:23,439: INFO/ForkPoolWorker-7] Task women.tasks.dbackup_task[634b65cc-9221-4edc-944b-5a011a2f2a3d] succeeded in 1.0387926670000027s: None
[2024-03-17 16:45:54,966: WARNING/MainProcess] /usr/local/lib/python3.12/site-packages/celery/worker/consumer/consumer.py:507: CPendingDeprecationWarning: The broker_connection_retry configuration setting will no longer determine
whether broker connection retries are made during startup in Celery 6.0 and above.
If you wish to retain the existing behavior for retrying connections on startup,
you should set broker_connection_retry_on_startup to True.
  warnings.warn(

[2024-03-17 16:45:55,012: INFO/MainProcess] Connected to redis://redis:6379/0
[2024-03-17 16:45:55,016: WARNING/MainProcess] /usr/local/lib/python3.12/site-packages/celery/worker/consumer/consumer.py:507: CPendingDeprecationWarning: The broker_connection_retry configuration setting will no longer determine
whether broker connection retries are made during startup in Celery 6.0 and above.
If you wish to retain the existing behavior for retrying connections on startup,
you should set broker_connection_retry_on_startup to True.
  warnings.warn(

[2024-03-17 16:45:55,022: INFO/MainProcess] mingle: searching for neighbors
[2024-03-17 16:45:56,044: INFO/MainProcess] mingle: all alone
[2024-03-17 16:45:56,078: INFO/MainProcess] celery@88b3bad385fe ready.
[2024-03-17 16:45:56,087: INFO/MainProcess] Task women.tasks.dbackup_task[c36cd40e-11f9-4340-8438-981cc2349aa7] received
[2024-03-17 16:45:56,272: WARNING/ForkPoolWorker-7] Waiting for database dump...
[2024-03-17 16:45:57,067: WARNING/ForkPoolWorker-7] Database successfully backed up
[2024-03-17 16:45:57,071: INFO/ForkPoolWorker-7] Task women.tasks.dbackup_task[c36cd40e-11f9-4340-8438-981cc2349aa7] succeeded in 0.9805881199999931s: None
[2024-03-18 12:03:03,318: INFO/MainProcess] Task women.tasks.dbackup_task[735dd5e6-7158-40d0-815d-e1f2d5c511c9] received
[2024-03-18 12:03:03,805: WARNING/ForkPoolWorker-7] Waiting for database dump...
[2024-03-18 12:03:04,901: WARNING/ForkPoolWorker-7] Database successfully backed up
[2024-03-18 12:03:04,916: INFO/ForkPoolWorker-7] Task women.tasks.dbackup_task[735dd5e6-7158-40d0-815d-e1f2d5c511c9] succeeded in 1.3511923520018172s: None
[2024-03-18 20:25:20,551: WARNING/MainProcess] /usr/local/lib/python3.12/site-packages/celery/worker/consumer/consumer.py:507: CPendingDeprecationWarning: The broker_connection_retry configuration setting will no longer determine
whether broker connection retries are made during startup in Celery 6.0 and above.
If you wish to retain the existing behavior for retrying connections on startup,
you should set broker_connection_retry_on_startup to True.
  warnings.warn(

[2024-03-18 20:25:25,396: ERROR/MainProcess] consumer: Cannot connect to redis://redis:6379/0: Error -3 connecting to redis:6379. Try again..
Trying again in 2.00 seconds... (1/100)

[2024-03-18 20:25:32,431: ERROR/MainProcess] consumer: Cannot connect to redis://redis:6379/0: Error -3 connecting to redis:6379. Try again..
Trying again in 4.00 seconds... (2/100)

[2024-03-18 20:25:41,709: ERROR/MainProcess] consumer: Cannot connect to redis://redis:6379/0: Error -3 connecting to redis:6379. Try again..
Trying again in 6.00 seconds... (3/100)

[2024-03-18 20:25:52,733: ERROR/MainProcess] consumer: Cannot connect to redis://redis:6379/0: Error -3 connecting to redis:6379. Try again..
Trying again in 8.00 seconds... (4/100)

[2024-03-18 20:26:04,929: ERROR/MainProcess] consumer: Cannot connect to redis://redis:6379/0: Error -3 connecting to redis:6379. Try again..
Trying again in 10.00 seconds... (5/100)

[2024-03-18 20:26:19,940: ERROR/MainProcess] consumer: Cannot connect to redis://redis:6379/0: Error -3 connecting to redis:6379. Try again..
Trying again in 12.00 seconds... (6/100)

[2024-03-18 20:26:37,372: ERROR/MainProcess] consumer: Cannot connect to redis://redis:6379/0: Error -3 connecting to redis:6379. Try again..
Trying again in 14.00 seconds... (7/100)

[2024-03-18 20:26:56,233: ERROR/MainProcess] consumer: Cannot connect to redis://redis:6379/0: Error -3 connecting to redis:6379. Try again..
Trying again in 16.00 seconds... (8/100)

[2024-03-18 20:27:37,208: WARNING/MainProcess] /usr/local/lib/python3.12/site-packages/celery/worker/consumer/consumer.py:507: CPendingDeprecationWarning: The broker_connection_retry configuration setting will no longer determine
whether broker connection retries are made during startup in Celery 6.0 and above.
If you wish to retain the existing behavior for retrying connections on startup,
you should set broker_connection_retry_on_startup to True.
  warnings.warn(

[2024-03-18 20:27:37,258: INFO/MainProcess] Connected to redis://redis:6379/0
[2024-03-18 20:27:37,262: WARNING/MainProcess] /usr/local/lib/python3.12/site-packages/celery/worker/consumer/consumer.py:507: CPendingDeprecationWarning: The broker_connection_retry configuration setting will no longer determine
whether broker connection retries are made during startup in Celery 6.0 and above.
If you wish to retain the existing behavior for retrying connections on startup,
you should set broker_connection_retry_on_startup to True.
  warnings.warn(

[2024-03-18 20:27:37,269: INFO/MainProcess] mingle: searching for neighbors
[2024-03-18 20:27:38,295: INFO/MainProcess] mingle: all alone
[2024-03-18 20:27:38,335: INFO/MainProcess] celery@88b3bad385fe ready.
[2024-03-18 20:52:05,408: WARNING/MainProcess] /usr/local/lib/python3.12/site-packages/celery/worker/consumer/consumer.py:507: CPendingDeprecationWarning: The broker_connection_retry configuration setting will no longer determine
whether broker connection retries are made during startup in Celery 6.0 and above.
If you wish to retain the existing behavior for retrying connections on startup,
you should set broker_connection_retry_on_startup to True.
  warnings.warn(

[2024-03-18 20:52:05,565: INFO/MainProcess] Connected to redis://redis:6379/0
[2024-03-18 20:52:05,582: WARNING/MainProcess] /usr/local/lib/python3.12/site-packages/celery/worker/consumer/consumer.py:507: CPendingDeprecationWarning: The broker_connection_retry configuration setting will no longer determine
whether broker connection retries are made during startup in Celery 6.0 and above.
If you wish to retain the existing behavior for retrying connections on startup,
you should set broker_connection_retry_on_startup to True.
  warnings.warn(

[2024-03-18 20:52:05,619: INFO/MainProcess] mingle: searching for neighbors
[2024-03-18 20:52:06,683: INFO/MainProcess] mingle: all alone
[2024-03-18 20:52:06,789: INFO/MainProcess] celery@c9b04d3367e3 ready.
[2024-04-01 18:57:54,598: WARNING/MainProcess] /usr/local/lib/python3.12/site-packages/celery/worker/consumer/consumer.py:507: CPendingDeprecationWarning: The broker_connection_retry configuration setting will no longer determine
whether broker connection retries are made during startup in Celery 6.0 and above.
If you wish to retain the existing behavior for retrying connections on startup,
you should set broker_connection_retry_on_startup to True.
  warnings.warn(

[2024-04-01 18:57:59,683: ERROR/MainProcess] consumer: Cannot connect to redis://redis:6379/0: Error -3 connecting to redis:6379. Try again..
Trying again in 2.00 seconds... (1/100)

[2024-04-01 18:58:06,691: ERROR/MainProcess] consumer: Cannot connect to redis://redis:6379/0: Error -3 connecting to redis:6379. Try again..
Trying again in 4.00 seconds... (2/100)

[2024-04-02 22:09:39,724: WARNING/MainProcess] /usr/local/lib/python3.12/site-packages/celery/worker/consumer/consumer.py:507: CPendingDeprecationWarning: The broker_connection_retry configuration setting will no longer determine
whether broker connection retries are made during startup in Celery 6.0 and above.
If you wish to retain the existing behavior for retrying connections on startup,
you should set broker_connection_retry_on_startup to True.
  warnings.warn(

[2024-04-02 22:09:44,821: ERROR/MainProcess] consumer: Cannot connect to redis://redis:6379/0: Error -3 connecting to redis:6379. Try again..
Trying again in 2.00 seconds... (1/100)

[2024-04-02 22:09:51,830: ERROR/MainProcess] consumer: Cannot connect to redis://redis:6379/0: Error -3 connecting to redis:6379. Try again..
Trying again in 4.00 seconds... (2/100)

[2024-04-02 22:10:00,840: ERROR/MainProcess] consumer: Cannot connect to redis://redis:6379/0: Error -3 connecting to redis:6379. Try again..
Trying again in 6.00 seconds... (3/100)

[2024-04-02 22:10:11,850: ERROR/MainProcess] consumer: Cannot connect to redis://redis:6379/0: Error -3 connecting to redis:6379. Try again..
Trying again in 8.00 seconds... (4/100)

[2024-04-02 22:10:24,859: ERROR/MainProcess] consumer: Cannot connect to redis://redis:6379/0: Error -3 connecting to redis:6379. Try again..
Trying again in 10.00 seconds... (5/100)

[2024-04-02 22:10:39,869: ERROR/MainProcess] consumer: Cannot connect to redis://redis:6379/0: Error -3 connecting to redis:6379. Try again..
Trying again in 12.00 seconds... (6/100)

[2024-04-02 22:10:56,878: ERROR/MainProcess] consumer: Cannot connect to redis://redis:6379/0: Error -3 connecting to redis:6379. Try again..
Trying again in 14.00 seconds... (7/100)

[2024-04-02 22:11:15,889: ERROR/MainProcess] consumer: Cannot connect to redis://redis:6379/0: Error -3 connecting to redis:6379. Try again..
Trying again in 16.00 seconds... (8/100)

[2024-04-02 22:11:36,900: ERROR/MainProcess] consumer: Cannot connect to redis://redis:6379/0: Error -3 connecting to redis:6379. Try again..
Trying again in 18.00 seconds... (9/100)

[2024-04-02 22:11:59,910: ERROR/MainProcess] consumer: Cannot connect to redis://redis:6379/0: Error -3 connecting to redis:6379. Try again..
Trying again in 20.00 seconds... (10/100)

[2024-04-02 22:12:24,925: ERROR/MainProcess] consumer: Cannot connect to redis://redis:6379/0: Error -3 connecting to redis:6379. Try again..
Trying again in 22.00 seconds... (11/100)

[2024-04-02 22:12:51,939: ERROR/MainProcess] consumer: Cannot connect to redis://redis:6379/0: Error -3 connecting to redis:6379. Try again..
Trying again in 24.00 seconds... (12/100)

[2024-04-02 22:13:20,957: ERROR/MainProcess] consumer: Cannot connect to redis://redis:6379/0: Error -3 connecting to redis:6379. Try again..
Trying again in 26.00 seconds... (13/100)

[2024-04-03 22:49:26,952: WARNING/MainProcess] /usr/local/lib/python3.12/site-packages/celery/worker/consumer/consumer.py:507: CPendingDeprecationWarning: The broker_connection_retry configuration setting will no longer determine
whether broker connection retries are made during startup in Celery 6.0 and above.
If you wish to retain the existing behavior for retrying connections on startup,
you should set broker_connection_retry_on_startup to True.
  warnings.warn(

[2024-04-03 22:49:27,351: INFO/MainProcess] Connected to redis://redis:6379/0
[2024-04-03 22:49:27,364: WARNING/MainProcess] /usr/local/lib/python3.12/site-packages/celery/worker/consumer/consumer.py:507: CPendingDeprecationWarning: The broker_connection_retry configuration setting will no longer determine
whether broker connection retries are made during startup in Celery 6.0 and above.
If you wish to retain the existing behavior for retrying connections on startup,
you should set broker_connection_retry_on_startup to True.
  warnings.warn(

[2024-04-03 22:49:27,377: INFO/MainProcess] mingle: searching for neighbors
[2024-04-03 22:49:28,424: INFO/MainProcess] mingle: all alone
[2024-04-03 22:49:28,512: INFO/MainProcess] celery@df9837129de4 ready.
[2024-04-03 22:49:28,539: INFO/MainProcess] Task women.tasks.dbackup_task[091f9e41-c504-4cae-8465-4e4fad579940] received
[2024-04-03 22:49:29,465: WARNING/ForkPoolWorker-7] Waiting for database dump...
[2024-04-03 22:49:36,063: ERROR/ForkPoolWorker-7] Task women.tasks.dbackup_task[091f9e41-c504-4cae-8465-4e4fad579940] raised unexpected: CommandError('Unable to serialize database: no such table: authtoken_token')
Traceback (most recent call last):
  File "/usr/local/lib/python3.12/site-packages/django/db/backends/utils.py", line 89, in _execute
    return self.cursor.execute(sql, params)
           ^^^^^^^^^^^^^^^^^^^^^^^^^^^^^^^^
  File "/usr/local/lib/python3.12/site-packages/django/db/backends/sqlite3/base.py", line 328, in execute
    return super().execute(query, params)
           ^^^^^^^^^^^^^^^^^^^^^^^^^^^^^^
sqlite3.OperationalError: no such table: authtoken_token

The above exception was the direct cause of the following exception:

Traceback (most recent call last):
  File "/usr/local/lib/python3.12/site-packages/django/core/management/commands/dumpdata.py", line 265, in handle
    serializers.serialize(
  File "/usr/local/lib/python3.12/site-packages/django/core/serializers/__init__.py", line 134, in serialize
    s.serialize(queryset, **options)
  File "/usr/local/lib/python3.12/site-packages/django/core/serializers/base.py", line 132, in serialize
    for count, obj in enumerate(queryset, start=1):
  File "/usr/local/lib/python3.12/site-packages/django/core/management/commands/dumpdata.py", line 222, in get_objects
    yield from queryset.iterator()
  File "/usr/local/lib/python3.12/site-packages/django/db/models/query.py", line 516, in _iterator
    yield from iterable
  File "/usr/local/lib/python3.12/site-packages/django/db/models/query.py", line 91, in __iter__
    results = compiler.execute_sql(
              ^^^^^^^^^^^^^^^^^^^^^
  File "/usr/local/lib/python3.12/site-packages/django/db/models/sql/compiler.py", line 1560, in execute_sql
    cursor.execute(sql, params)
  File "/usr/local/lib/python3.12/site-packages/django/db/backends/utils.py", line 102, in execute
    return super().execute(sql, params)
           ^^^^^^^^^^^^^^^^^^^^^^^^^^^^
  File "/usr/local/lib/python3.12/site-packages/django/db/backends/utils.py", line 67, in execute
    return self._execute_with_wrappers(
           ^^^^^^^^^^^^^^^^^^^^^^^^^^^^
  File "/usr/local/lib/python3.12/site-packages/django/db/backends/utils.py", line 80, in _execute_with_wrappers
    return executor(sql, params, many, context)
           ^^^^^^^^^^^^^^^^^^^^^^^^^^^^^^^^^^^^
  File "/usr/local/lib/python3.12/site-packages/django/db/backends/utils.py", line 84, in _execute
    with self.db.wrap_database_errors:
  File "/usr/local/lib/python3.12/site-packages/django/db/utils.py", line 91, in __exit__
    raise dj_exc_value.with_traceback(traceback) from exc_value
  File "/usr/local/lib/python3.12/site-packages/django/db/backends/utils.py", line 89, in _execute
    return self.cursor.execute(sql, params)
           ^^^^^^^^^^^^^^^^^^^^^^^^^^^^^^^^
  File "/usr/local/lib/python3.12/site-packages/django/db/backends/sqlite3/base.py", line 328, in execute
    return super().execute(query, params)
           ^^^^^^^^^^^^^^^^^^^^^^^^^^^^^^
django.db.utils.OperationalError: no such table: authtoken_token

During handling of the above exception, another exception occurred:

Traceback (most recent call last):
  File "/usr/local/lib/python3.12/site-packages/celery/app/trace.py", line 477, in trace_task
    R = retval = fun(*args, **kwargs)
                 ^^^^^^^^^^^^^^^^^^^^
  File "/usr/local/lib/python3.12/site-packages/celery/app/trace.py", line 760, in __protected_call__
    return self.run(*args, **kwargs)
           ^^^^^^^^^^^^^^^^^^^^^^^^^
  File "/app/women/tasks.py", line 29, in dbackup_task
    call_command('dbackup')
  File "/usr/local/lib/python3.12/site-packages/django/core/management/__init__.py", line 194, in call_command
    return command.execute(*args, **defaults)
           ^^^^^^^^^^^^^^^^^^^^^^^^^^^^^^^^^^
  File "/usr/local/lib/python3.12/site-packages/django/core/management/base.py", line 458, in execute
    output = self.handle(*args, **options)
             ^^^^^^^^^^^^^^^^^^^^^^^^^^^^^
  File "/app/women/management/commands/dbackup.py", line 11, in handle
    call_command(
  File "/usr/local/lib/python3.12/site-packages/django/core/management/__init__.py", line 194, in call_command
    return command.execute(*args, **defaults)
           ^^^^^^^^^^^^^^^^^^^^^^^^^^^^^^^^^^
  File "/usr/local/lib/python3.12/site-packages/django_dump_load_utf8/management/commands/dumpdatautf8.py", line 10, in execute
    result = super(Command, self).execute(*args, **options)
             ^^^^^^^^^^^^^^^^^^^^^^^^^^^^^^^^^^^^^^^^^^^^^^
  File "/usr/local/lib/python3.12/site-packages/django/core/management/base.py", line 458, in execute
    output = self.handle(*args, **options)
             ^^^^^^^^^^^^^^^^^^^^^^^^^^^^^
  File "/usr/local/lib/python3.12/site-packages/django/core/management/commands/dumpdata.py", line 281, in handle
    raise CommandError("Unable to serialize database: %s" % e)
django.core.management.base.CommandError: Unable to serialize database: no such table: authtoken_token
[2024-04-03 23:23:20,974: WARNING/MainProcess] /usr/local/lib/python3.12/site-packages/celery/worker/consumer/consumer.py:507: CPendingDeprecationWarning: The broker_connection_retry configuration setting will no longer determine
whether broker connection retries are made during startup in Celery 6.0 and above.
If you wish to retain the existing behavior for retrying connections on startup,
you should set broker_connection_retry_on_startup to True.
  warnings.warn(

[2024-04-03 23:23:21,060: INFO/MainProcess] Connected to redis://redis:6379/0
[2024-04-03 23:23:21,076: WARNING/MainProcess] /usr/local/lib/python3.12/site-packages/celery/worker/consumer/consumer.py:507: CPendingDeprecationWarning: The broker_connection_retry configuration setting will no longer determine
whether broker connection retries are made during startup in Celery 6.0 and above.
If you wish to retain the existing behavior for retrying connections on startup,
you should set broker_connection_retry_on_startup to True.
  warnings.warn(

[2024-04-03 23:23:21,110: INFO/MainProcess] mingle: searching for neighbors
[2024-04-03 23:23:22,198: INFO/MainProcess] mingle: all alone
[2024-04-03 23:23:22,325: INFO/MainProcess] celery@726e6b764f0a ready.
[2024-04-03 23:27:17,424: WARNING/MainProcess] /usr/local/lib/python3.12/site-packages/celery/worker/consumer/consumer.py:507: CPendingDeprecationWarning: The broker_connection_retry configuration setting will no longer determine
whether broker connection retries are made during startup in Celery 6.0 and above.
If you wish to retain the existing behavior for retrying connections on startup,
you should set broker_connection_retry_on_startup to True.
  warnings.warn(

[2024-04-03 23:27:17,484: INFO/MainProcess] Connected to redis://redis:6379/0
[2024-04-03 23:27:17,507: WARNING/MainProcess] /usr/local/lib/python3.12/site-packages/celery/worker/consumer/consumer.py:507: CPendingDeprecationWarning: The broker_connection_retry configuration setting will no longer determine
whether broker connection retries are made during startup in Celery 6.0 and above.
If you wish to retain the existing behavior for retrying connections on startup,
you should set broker_connection_retry_on_startup to True.
  warnings.warn(

[2024-04-03 23:27:17,544: INFO/MainProcess] mingle: searching for neighbors
[2024-04-03 23:27:18,602: INFO/MainProcess] mingle: all alone
[2024-04-03 23:27:18,649: INFO/MainProcess] celery@a8c0d8955eca ready.
[2024-04-03 23:41:50,668: WARNING/MainProcess] /usr/local/lib/python3.12/site-packages/celery/worker/consumer/consumer.py:507: CPendingDeprecationWarning: The broker_connection_retry configuration setting will no longer determine
whether broker connection retries are made during startup in Celery 6.0 and above.
If you wish to retain the existing behavior for retrying connections on startup,
you should set broker_connection_retry_on_startup to True.
  warnings.warn(

[2024-04-03 23:41:50,821: INFO/MainProcess] Connected to redis://redis:6379/0
[2024-04-03 23:41:50,853: WARNING/MainProcess] /usr/local/lib/python3.12/site-packages/celery/worker/consumer/consumer.py:507: CPendingDeprecationWarning: The broker_connection_retry configuration setting will no longer determine
whether broker connection retries are made during startup in Celery 6.0 and above.
If you wish to retain the existing behavior for retrying connections on startup,
you should set broker_connection_retry_on_startup to True.
  warnings.warn(

[2024-04-03 23:41:50,875: INFO/MainProcess] mingle: searching for neighbors
[2024-04-03 23:41:51,986: INFO/MainProcess] mingle: all alone
[2024-04-03 23:41:52,148: INFO/MainProcess] celery@0eb42864a29d ready.
[2024-04-03 23:51:13,960: WARNING/MainProcess] /usr/local/lib/python3.12/site-packages/celery/worker/consumer/consumer.py:507: CPendingDeprecationWarning: The broker_connection_retry configuration setting will no longer determine
whether broker connection retries are made during startup in Celery 6.0 and above.
If you wish to retain the existing behavior for retrying connections on startup,
you should set broker_connection_retry_on_startup to True.
  warnings.warn(

[2024-04-03 23:51:13,985: INFO/MainProcess] Connected to redis://redis:6379/0
[2024-04-03 23:51:13,991: WARNING/MainProcess] /usr/local/lib/python3.12/site-packages/celery/worker/consumer/consumer.py:507: CPendingDeprecationWarning: The broker_connection_retry configuration setting will no longer determine
whether broker connection retries are made during startup in Celery 6.0 and above.
If you wish to retain the existing behavior for retrying connections on startup,
you should set broker_connection_retry_on_startup to True.
  warnings.warn(

[2024-04-03 23:51:14,000: INFO/MainProcess] mingle: searching for neighbors
[2024-04-03 23:51:15,028: INFO/MainProcess] mingle: all alone
[2024-04-03 23:51:15,395: INFO/MainProcess] celery@69da9331a2ce ready.
[2024-04-04 00:13:23,154: WARNING/MainProcess] /usr/local/lib/python3.12/site-packages/celery/worker/consumer/consumer.py:507: CPendingDeprecationWarning: The broker_connection_retry configuration setting will no longer determine
whether broker connection retries are made during startup in Celery 6.0 and above.
If you wish to retain the existing behavior for retrying connections on startup,
you should set broker_connection_retry_on_startup to True.
  warnings.warn(

[2024-04-04 00:13:23,224: INFO/MainProcess] Connected to redis://redis:6379/0
[2024-04-04 00:13:23,235: WARNING/MainProcess] /usr/local/lib/python3.12/site-packages/celery/worker/consumer/consumer.py:507: CPendingDeprecationWarning: The broker_connection_retry configuration setting will no longer determine
whether broker connection retries are made during startup in Celery 6.0 and above.
If you wish to retain the existing behavior for retrying connections on startup,
you should set broker_connection_retry_on_startup to True.
  warnings.warn(

[2024-04-04 00:13:23,251: INFO/MainProcess] mingle: searching for neighbors
[2024-04-04 00:13:24,311: INFO/MainProcess] mingle: all alone
[2024-04-04 00:13:24,420: INFO/MainProcess] celery@6adaea5e43d0 ready.
[2024-04-04 22:19:36,295: WARNING/MainProcess] /usr/local/lib/python3.12/site-packages/celery/worker/consumer/consumer.py:507: CPendingDeprecationWarning: The broker_connection_retry configuration setting will no longer determine
whether broker connection retries are made during startup in Celery 6.0 and above.
If you wish to retain the existing behavior for retrying connections on startup,
you should set broker_connection_retry_on_startup to True.
  warnings.warn(

[2024-04-04 22:19:41,310: ERROR/MainProcess] consumer: Cannot connect to redis://redis:6379/0: Error -3 connecting to redis:6379. Try again..
Trying again in 2.00 seconds... (1/100)

[2024-04-04 22:20:08,007: WARNING/MainProcess] /usr/local/lib/python3.12/site-packages/celery/worker/consumer/consumer.py:507: CPendingDeprecationWarning: The broker_connection_retry configuration setting will no longer determine
whether broker connection retries are made during startup in Celery 6.0 and above.
If you wish to retain the existing behavior for retrying connections on startup,
you should set broker_connection_retry_on_startup to True.
  warnings.warn(

[2024-04-04 22:20:08,028: INFO/MainProcess] Connected to redis://redis:6379/0
[2024-04-04 22:20:08,033: WARNING/MainProcess] /usr/local/lib/python3.12/site-packages/celery/worker/consumer/consumer.py:507: CPendingDeprecationWarning: The broker_connection_retry configuration setting will no longer determine
whether broker connection retries are made during startup in Celery 6.0 and above.
If you wish to retain the existing behavior for retrying connections on startup,
you should set broker_connection_retry_on_startup to True.
  warnings.warn(

[2024-04-04 22:20:08,041: INFO/MainProcess] mingle: searching for neighbors
[2024-04-04 22:20:09,068: INFO/MainProcess] mingle: all alone
[2024-04-04 22:20:09,103: INFO/MainProcess] celery@6adaea5e43d0 ready.
[2024-04-04 22:20:09,112: INFO/MainProcess] Task women.tasks.dbackup_task[191c7d20-49e3-4a52-938f-2de6072cbde9] received
[2024-04-04 22:20:09,256: WARNING/ForkPoolWorker-7] Waiting for database dump...
[2024-04-04 22:20:10,213: WARNING/ForkPoolWorker-7] Database successfully backed up
[2024-04-04 22:20:10,217: INFO/ForkPoolWorker-7] Task women.tasks.dbackup_task[191c7d20-49e3-4a52-938f-2de6072cbde9] succeeded in 1.1013324520000012s: None
[2024-04-04 23:56:56,289: WARNING/MainProcess] /usr/local/lib/python3.12/site-packages/celery/worker/consumer/consumer.py:507: CPendingDeprecationWarning: The broker_connection_retry configuration setting will no longer determine
whether broker connection retries are made during startup in Celery 6.0 and above.
If you wish to retain the existing behavior for retrying connections on startup,
you should set broker_connection_retry_on_startup to True.
  warnings.warn(

[2024-04-04 23:56:57,468: INFO/MainProcess] Connected to redis://redis:6379/0
[2024-04-04 23:56:57,496: WARNING/MainProcess] /usr/local/lib/python3.12/site-packages/celery/worker/consumer/consumer.py:507: CPendingDeprecationWarning: The broker_connection_retry configuration setting will no longer determine
whether broker connection retries are made during startup in Celery 6.0 and above.
If you wish to retain the existing behavior for retrying connections on startup,
you should set broker_connection_retry_on_startup to True.
  warnings.warn(

[2024-04-04 23:56:57,516: INFO/MainProcess] mingle: searching for neighbors
[2024-04-04 23:56:58,592: INFO/MainProcess] mingle: all alone
[2024-04-04 23:56:58,725: INFO/MainProcess] celery@2845d27fc9fb ready.
[2024-04-05 00:23:17,375: WARNING/MainProcess] /usr/local/lib/python3.12/site-packages/celery/worker/consumer/consumer.py:507: CPendingDeprecationWarning: The broker_connection_retry configuration setting will no longer determine
whether broker connection retries are made during startup in Celery 6.0 and above.
If you wish to retain the existing behavior for retrying connections on startup,
you should set broker_connection_retry_on_startup to True.
  warnings.warn(

[2024-04-05 00:23:17,447: INFO/MainProcess] Connected to redis://redis:6379/0
[2024-04-05 00:23:17,456: WARNING/MainProcess] /usr/local/lib/python3.12/site-packages/celery/worker/consumer/consumer.py:507: CPendingDeprecationWarning: The broker_connection_retry configuration setting will no longer determine
whether broker connection retries are made during startup in Celery 6.0 and above.
If you wish to retain the existing behavior for retrying connections on startup,
you should set broker_connection_retry_on_startup to True.
  warnings.warn(

[2024-04-05 00:23:17,480: INFO/MainProcess] mingle: searching for neighbors
[2024-04-05 00:23:18,553: INFO/MainProcess] mingle: all alone
[2024-04-05 00:23:18,674: INFO/MainProcess] celery@03c34c5afd4c ready.
[2024-04-05 00:37:49,163: WARNING/MainProcess] /usr/local/lib/python3.12/site-packages/celery/worker/consumer/consumer.py:507: CPendingDeprecationWarning: The broker_connection_retry configuration setting will no longer determine
whether broker connection retries are made during startup in Celery 6.0 and above.
If you wish to retain the existing behavior for retrying connections on startup,
you should set broker_connection_retry_on_startup to True.
  warnings.warn(

[2024-04-05 00:37:50,018: INFO/MainProcess] Connected to redis://redis:6379/0
[2024-04-05 00:37:50,024: WARNING/MainProcess] /usr/local/lib/python3.12/site-packages/celery/worker/consumer/consumer.py:507: CPendingDeprecationWarning: The broker_connection_retry configuration setting will no longer determine
whether broker connection retries are made during startup in Celery 6.0 and above.
If you wish to retain the existing behavior for retrying connections on startup,
you should set broker_connection_retry_on_startup to True.
  warnings.warn(

[2024-04-05 00:37:50,032: INFO/MainProcess] mingle: searching for neighbors
[2024-04-05 00:37:51,061: INFO/MainProcess] mingle: all alone
[2024-04-05 00:37:51,108: INFO/MainProcess] celery@2a3bc287ac5d ready.
[2024-04-05 01:18:28,519: WARNING/MainProcess] /usr/local/lib/python3.12/site-packages/celery/worker/consumer/consumer.py:507: CPendingDeprecationWarning: The broker_connection_retry configuration setting will no longer determine
whether broker connection retries are made during startup in Celery 6.0 and above.
If you wish to retain the existing behavior for retrying connections on startup,
you should set broker_connection_retry_on_startup to True.
  warnings.warn(

[2024-04-05 01:18:28,543: INFO/MainProcess] Connected to redis://redis:6379/0
[2024-04-05 01:18:28,549: WARNING/MainProcess] /usr/local/lib/python3.12/site-packages/celery/worker/consumer/consumer.py:507: CPendingDeprecationWarning: The broker_connection_retry configuration setting will no longer determine
whether broker connection retries are made during startup in Celery 6.0 and above.
If you wish to retain the existing behavior for retrying connections on startup,
you should set broker_connection_retry_on_startup to True.
  warnings.warn(

[2024-04-05 01:18:28,559: INFO/MainProcess] mingle: searching for neighbors
[2024-04-05 01:18:29,585: INFO/MainProcess] mingle: all alone
[2024-04-05 01:18:29,624: INFO/MainProcess] celery@2a3bc287ac5d ready.
[2024-04-05 01:18:29,639: INFO/MainProcess] Task women.tasks.dbackup_task[aa4c12b7-bd0a-4900-940a-9072d28d791b] received
[2024-04-05 01:18:29,776: WARNING/ForkPoolWorker-7] Waiting for database dump...
[2024-04-05 01:18:30,142: WARNING/ForkPoolWorker-7] Database successfully backed up
[2024-04-05 01:18:30,146: INFO/ForkPoolWorker-7] Task women.tasks.dbackup_task[aa4c12b7-bd0a-4900-940a-9072d28d791b] succeeded in 0.5039123879996623s: None
[2024-04-05 01:41:52,851: WARNING/MainProcess] /usr/local/lib/python3.12/site-packages/celery/worker/consumer/consumer.py:507: CPendingDeprecationWarning: The broker_connection_retry configuration setting will no longer determine
whether broker connection retries are made during startup in Celery 6.0 and above.
If you wish to retain the existing behavior for retrying connections on startup,
you should set broker_connection_retry_on_startup to True.
  warnings.warn(

[2024-04-05 01:41:52,888: INFO/MainProcess] Connected to redis://redis:6379/0
[2024-04-05 01:41:52,895: WARNING/MainProcess] /usr/local/lib/python3.12/site-packages/celery/worker/consumer/consumer.py:507: CPendingDeprecationWarning: The broker_connection_retry configuration setting will no longer determine
whether broker connection retries are made during startup in Celery 6.0 and above.
If you wish to retain the existing behavior for retrying connections on startup,
you should set broker_connection_retry_on_startup to True.
  warnings.warn(

[2024-04-05 01:41:52,921: INFO/MainProcess] mingle: searching for neighbors
[2024-04-05 01:41:53,958: INFO/MainProcess] mingle: all alone
[2024-04-05 01:41:54,037: INFO/MainProcess] celery@bd64390a16ff ready.
[2024-04-05 01:45:10,035: WARNING/MainProcess] /usr/local/lib/python3.12/site-packages/celery/worker/consumer/consumer.py:507: CPendingDeprecationWarning: The broker_connection_retry configuration setting will no longer determine
whether broker connection retries are made during startup in Celery 6.0 and above.
If you wish to retain the existing behavior for retrying connections on startup,
you should set broker_connection_retry_on_startup to True.
  warnings.warn(

[2024-04-05 01:45:10,496: INFO/MainProcess] Connected to redis://redis:6379/0
[2024-04-05 01:45:10,502: WARNING/MainProcess] /usr/local/lib/python3.12/site-packages/celery/worker/consumer/consumer.py:507: CPendingDeprecationWarning: The broker_connection_retry configuration setting will no longer determine
whether broker connection retries are made during startup in Celery 6.0 and above.
If you wish to retain the existing behavior for retrying connections on startup,
you should set broker_connection_retry_on_startup to True.
  warnings.warn(

[2024-04-05 01:45:10,518: INFO/MainProcess] mingle: searching for neighbors
[2024-04-05 01:45:11,544: INFO/MainProcess] mingle: all alone
[2024-04-05 01:45:11,593: INFO/MainProcess] celery@db3e16846eb0 ready.
[2024-04-05 01:48:06,620: WARNING/MainProcess] /usr/local/lib/python3.12/site-packages/celery/worker/consumer/consumer.py:507: CPendingDeprecationWarning: The broker_connection_retry configuration setting will no longer determine
whether broker connection retries are made during startup in Celery 6.0 and above.
If you wish to retain the existing behavior for retrying connections on startup,
you should set broker_connection_retry_on_startup to True.
  warnings.warn(

[2024-04-05 01:48:06,654: INFO/MainProcess] Connected to redis://redis:6379/0
[2024-04-05 01:48:06,661: WARNING/MainProcess] /usr/local/lib/python3.12/site-packages/celery/worker/consumer/consumer.py:507: CPendingDeprecationWarning: The broker_connection_retry configuration setting will no longer determine
whether broker connection retries are made during startup in Celery 6.0 and above.
If you wish to retain the existing behavior for retrying connections on startup,
you should set broker_connection_retry_on_startup to True.
  warnings.warn(

[2024-04-05 01:48:06,672: INFO/MainProcess] mingle: searching for neighbors
[2024-04-05 01:48:07,716: INFO/MainProcess] mingle: all alone
[2024-04-05 01:48:07,763: INFO/MainProcess] celery@db3e16846eb0 ready.
[2024-04-05 02:48:42,767: WARNING/MainProcess] /usr/local/lib/python3.12/site-packages/celery/worker/consumer/consumer.py:507: CPendingDeprecationWarning: The broker_connection_retry configuration setting will no longer determine
whether broker connection retries are made during startup in Celery 6.0 and above.
If you wish to retain the existing behavior for retrying connections on startup,
you should set broker_connection_retry_on_startup to True.
  warnings.warn(

[2024-04-05 02:48:42,791: INFO/MainProcess] Connected to redis://redis:6379/0
[2024-04-05 02:48:42,795: WARNING/MainProcess] /usr/local/lib/python3.12/site-packages/celery/worker/consumer/consumer.py:507: CPendingDeprecationWarning: The broker_connection_retry configuration setting will no longer determine
whether broker connection retries are made during startup in Celery 6.0 and above.
If you wish to retain the existing behavior for retrying connections on startup,
you should set broker_connection_retry_on_startup to True.
  warnings.warn(

[2024-04-05 02:48:42,804: INFO/MainProcess] mingle: searching for neighbors
[2024-04-05 02:48:43,833: INFO/MainProcess] mingle: all alone
[2024-04-05 02:48:43,874: INFO/MainProcess] celery@db3e16846eb0 ready.
[2024-04-05 03:05:05,918: WARNING/MainProcess] /usr/local/lib/python3.12/site-packages/celery/worker/consumer/consumer.py:507: CPendingDeprecationWarning: The broker_connection_retry configuration setting will no longer determine
whether broker connection retries are made during startup in Celery 6.0 and above.
If you wish to retain the existing behavior for retrying connections on startup,
you should set broker_connection_retry_on_startup to True.
  warnings.warn(

[2024-04-05 03:05:05,942: INFO/MainProcess] Connected to redis://redis:6379/0
[2024-04-05 03:05:05,947: WARNING/MainProcess] /usr/local/lib/python3.12/site-packages/celery/worker/consumer/consumer.py:507: CPendingDeprecationWarning: The broker_connection_retry configuration setting will no longer determine
whether broker connection retries are made during startup in Celery 6.0 and above.
If you wish to retain the existing behavior for retrying connections on startup,
you should set broker_connection_retry_on_startup to True.
  warnings.warn(

[2024-04-05 03:05:05,955: INFO/MainProcess] mingle: searching for neighbors
[2024-04-05 03:05:06,980: INFO/MainProcess] mingle: all alone
[2024-04-05 03:05:07,018: INFO/MainProcess] celery@db3e16846eb0 ready.
[2024-04-05 03:07:49,130: WARNING/MainProcess] /usr/local/lib/python3.12/site-packages/celery/worker/consumer/consumer.py:507: CPendingDeprecationWarning: The broker_connection_retry configuration setting will no longer determine
whether broker connection retries are made during startup in Celery 6.0 and above.
If you wish to retain the existing behavior for retrying connections on startup,
you should set broker_connection_retry_on_startup to True.
  warnings.warn(

[2024-04-05 03:07:49,153: INFO/MainProcess] Connected to redis://redis:6379/0
[2024-04-05 03:07:49,157: WARNING/MainProcess] /usr/local/lib/python3.12/site-packages/celery/worker/consumer/consumer.py:507: CPendingDeprecationWarning: The broker_connection_retry configuration setting will no longer determine
whether broker connection retries are made during startup in Celery 6.0 and above.
If you wish to retain the existing behavior for retrying connections on startup,
you should set broker_connection_retry_on_startup to True.
  warnings.warn(

[2024-04-05 03:07:49,165: INFO/MainProcess] mingle: searching for neighbors
[2024-04-05 03:07:50,189: INFO/MainProcess] mingle: all alone
[2024-04-05 03:07:50,229: INFO/MainProcess] celery@db3e16846eb0 ready.
[2024-04-05 03:20:09,007: WARNING/MainProcess] /usr/local/lib/python3.12/site-packages/celery/worker/consumer/consumer.py:507: CPendingDeprecationWarning: The broker_connection_retry configuration setting will no longer determine
whether broker connection retries are made during startup in Celery 6.0 and above.
If you wish to retain the existing behavior for retrying connections on startup,
you should set broker_connection_retry_on_startup to True.
  warnings.warn(

[2024-04-05 03:20:09,644: INFO/MainProcess] Connected to redis://redis:6379/0
[2024-04-05 03:20:09,659: WARNING/MainProcess] /usr/local/lib/python3.12/site-packages/celery/worker/consumer/consumer.py:507: CPendingDeprecationWarning: The broker_connection_retry configuration setting will no longer determine
whether broker connection retries are made during startup in Celery 6.0 and above.
If you wish to retain the existing behavior for retrying connections on startup,
you should set broker_connection_retry_on_startup to True.
  warnings.warn(

[2024-04-05 03:20:09,678: INFO/MainProcess] mingle: searching for neighbors
[2024-04-05 03:20:10,745: INFO/MainProcess] mingle: all alone
[2024-04-05 03:20:10,857: INFO/MainProcess] celery@8a0a84fa708c ready.
[2024-04-05 03:22:21,286: WARNING/MainProcess] /usr/local/lib/python3.12/site-packages/celery/worker/consumer/consumer.py:507: CPendingDeprecationWarning: The broker_connection_retry configuration setting will no longer determine
whether broker connection retries are made during startup in Celery 6.0 and above.
If you wish to retain the existing behavior for retrying connections on startup,
you should set broker_connection_retry_on_startup to True.
  warnings.warn(

[2024-04-05 03:22:21,346: INFO/MainProcess] Connected to redis://redis:6379/0
[2024-04-05 03:22:21,363: WARNING/MainProcess] /usr/local/lib/python3.12/site-packages/celery/worker/consumer/consumer.py:507: CPendingDeprecationWarning: The broker_connection_retry configuration setting will no longer determine
whether broker connection retries are made during startup in Celery 6.0 and above.
If you wish to retain the existing behavior for retrying connections on startup,
you should set broker_connection_retry_on_startup to True.
  warnings.warn(

[2024-04-05 03:22:21,393: INFO/MainProcess] mingle: searching for neighbors
[2024-04-05 03:22:22,457: INFO/MainProcess] mingle: all alone
[2024-04-05 03:22:23,297: INFO/MainProcess] celery@8a0a84fa708c ready.
[2024-04-08 22:32:06,615: WARNING/MainProcess] /usr/local/lib/python3.12/site-packages/celery/worker/consumer/consumer.py:507: CPendingDeprecationWarning: The broker_connection_retry configuration setting will no longer determine
whether broker connection retries are made during startup in Celery 6.0 and above.
If you wish to retain the existing behavior for retrying connections on startup,
you should set broker_connection_retry_on_startup to True.
  warnings.warn(

[2024-04-08 22:32:11,629: ERROR/MainProcess] consumer: Cannot connect to redis://redis:6379/0: Error -3 connecting to redis:6379. Try again..
Trying again in 2.00 seconds... (1/100)

[2024-04-08 22:32:18,641: ERROR/MainProcess] consumer: Cannot connect to redis://redis:6379/0: Error -3 connecting to redis:6379. Try again..
Trying again in 4.00 seconds... (2/100)

[2024-04-08 22:32:27,649: ERROR/MainProcess] consumer: Cannot connect to redis://redis:6379/0: Error -3 connecting to redis:6379. Try again..
Trying again in 6.00 seconds... (3/100)

[2024-04-08 22:33:35,392: WARNING/MainProcess] /usr/local/lib/python3.12/site-packages/celery/worker/consumer/consumer.py:507: CPendingDeprecationWarning: The broker_connection_retry configuration setting will no longer determine
whether broker connection retries are made during startup in Celery 6.0 and above.
If you wish to retain the existing behavior for retrying connections on startup,
you should set broker_connection_retry_on_startup to True.
  warnings.warn(

[2024-04-08 22:33:35,414: INFO/MainProcess] Connected to redis://redis:6379/0
[2024-04-08 22:33:35,418: WARNING/MainProcess] /usr/local/lib/python3.12/site-packages/celery/worker/consumer/consumer.py:507: CPendingDeprecationWarning: The broker_connection_retry configuration setting will no longer determine
whether broker connection retries are made during startup in Celery 6.0 and above.
If you wish to retain the existing behavior for retrying connections on startup,
you should set broker_connection_retry_on_startup to True.
  warnings.warn(

[2024-04-08 22:33:35,425: INFO/MainProcess] mingle: searching for neighbors
[2024-04-08 22:33:36,448: INFO/MainProcess] mingle: all alone
[2024-04-08 22:33:36,481: INFO/MainProcess] celery@8a0a84fa708c ready.
[2024-04-08 22:33:36,490: INFO/MainProcess] Task women.tasks.dbackup_task[5bd747da-6b06-439b-b632-bb56e0d25e35] received
[2024-04-08 22:33:36,653: WARNING/ForkPoolWorker-7] Waiting for database dump...
[2024-04-08 22:33:37,326: ERROR/ForkPoolWorker-7] Task women.tasks.dbackup_task[5bd747da-6b06-439b-b632-bb56e0d25e35] raised unexpected: CommandError('Unable to serialize database: relation "django_site" does not exist\nLINE 1: ..."django_site"."domain", "django_site"."name" FROM "django_si...\n                                                             ^')
Traceback (most recent call last):
  File "/usr/local/lib/python3.12/site-packages/django/db/backends/utils.py", line 89, in _execute
    return self.cursor.execute(sql, params)
           ^^^^^^^^^^^^^^^^^^^^^^^^^^^^^^^^
  File "/usr/local/lib/python3.12/site-packages/psycopg/server_cursor.py", line 292, in execute
    raise ex.with_traceback(None)
psycopg.errors.UndefinedTable: relation "django_site" does not exist
LINE 1: ..."django_site"."domain", "django_site"."name" FROM "django_si...
                                                             ^

The above exception was the direct cause of the following exception:

Traceback (most recent call last):
  File "/usr/local/lib/python3.12/site-packages/django/core/management/commands/dumpdata.py", line 265, in handle
    serializers.serialize(
  File "/usr/local/lib/python3.12/site-packages/django/core/serializers/__init__.py", line 134, in serialize
    s.serialize(queryset, **options)
  File "/usr/local/lib/python3.12/site-packages/django/core/serializers/base.py", line 132, in serialize
    for count, obj in enumerate(queryset, start=1):
  File "/usr/local/lib/python3.12/site-packages/django/core/management/commands/dumpdata.py", line 222, in get_objects
    yield from queryset.iterator()
  File "/usr/local/lib/python3.12/site-packages/django/db/models/query.py", line 516, in _iterator
    yield from iterable
  File "/usr/local/lib/python3.12/site-packages/django/db/models/query.py", line 91, in __iter__
    results = compiler.execute_sql(
              ^^^^^^^^^^^^^^^^^^^^^
  File "/usr/local/lib/python3.12/site-packages/django/db/models/sql/compiler.py", line 1560, in execute_sql
    cursor.execute(sql, params)
  File "/usr/local/lib/python3.12/site-packages/django/db/backends/utils.py", line 102, in execute
    return super().execute(sql, params)
           ^^^^^^^^^^^^^^^^^^^^^^^^^^^^
  File "/usr/local/lib/python3.12/site-packages/django/db/backends/utils.py", line 67, in execute
    return self._execute_with_wrappers(
           ^^^^^^^^^^^^^^^^^^^^^^^^^^^^
  File "/usr/local/lib/python3.12/site-packages/django/db/backends/utils.py", line 80, in _execute_with_wrappers
    return executor(sql, params, many, context)
           ^^^^^^^^^^^^^^^^^^^^^^^^^^^^^^^^^^^^
  File "/usr/local/lib/python3.12/site-packages/django/db/backends/utils.py", line 84, in _execute
    with self.db.wrap_database_errors:
  File "/usr/local/lib/python3.12/site-packages/django/db/utils.py", line 91, in __exit__
    raise dj_exc_value.with_traceback(traceback) from exc_value
  File "/usr/local/lib/python3.12/site-packages/django/db/backends/utils.py", line 89, in _execute
    return self.cursor.execute(sql, params)
           ^^^^^^^^^^^^^^^^^^^^^^^^^^^^^^^^
  File "/usr/local/lib/python3.12/site-packages/psycopg/server_cursor.py", line 292, in execute
    raise ex.with_traceback(None)
django.db.utils.ProgrammingError: relation "django_site" does not exist
LINE 1: ..."django_site"."domain", "django_site"."name" FROM "django_si...
                                                             ^

During handling of the above exception, another exception occurred:

Traceback (most recent call last):
  File "/usr/local/lib/python3.12/site-packages/celery/app/trace.py", line 477, in trace_task
    R = retval = fun(*args, **kwargs)
                 ^^^^^^^^^^^^^^^^^^^^
  File "/usr/local/lib/python3.12/site-packages/celery/app/trace.py", line 760, in __protected_call__
    return self.run(*args, **kwargs)
           ^^^^^^^^^^^^^^^^^^^^^^^^^
  File "/app/women/tasks.py", line 29, in dbackup_task
    call_command('dbackup')
  File "/usr/local/lib/python3.12/site-packages/django/core/management/__init__.py", line 194, in call_command
    return command.execute(*args, **defaults)
           ^^^^^^^^^^^^^^^^^^^^^^^^^^^^^^^^^^
  File "/usr/local/lib/python3.12/site-packages/django/core/management/base.py", line 458, in execute
    output = self.handle(*args, **options)
             ^^^^^^^^^^^^^^^^^^^^^^^^^^^^^
  File "/app/women/management/commands/dbackup.py", line 11, in handle
    call_command(
  File "/usr/local/lib/python3.12/site-packages/django/core/management/__init__.py", line 194, in call_command
    return command.execute(*args, **defaults)
           ^^^^^^^^^^^^^^^^^^^^^^^^^^^^^^^^^^
  File "/usr/local/lib/python3.12/site-packages/django_dump_load_utf8/management/commands/dumpdatautf8.py", line 10, in execute
    result = super(Command, self).execute(*args, **options)
             ^^^^^^^^^^^^^^^^^^^^^^^^^^^^^^^^^^^^^^^^^^^^^^
  File "/usr/local/lib/python3.12/site-packages/django/core/management/base.py", line 458, in execute
    output = self.handle(*args, **options)
             ^^^^^^^^^^^^^^^^^^^^^^^^^^^^^
  File "/usr/local/lib/python3.12/site-packages/django/core/management/commands/dumpdata.py", line 281, in handle
    raise CommandError("Unable to serialize database: %s" % e)
django.core.management.base.CommandError: Unable to serialize database: relation "django_site" does not exist
LINE 1: ..."django_site"."domain", "django_site"."name" FROM "django_si...
                                                             ^
[2024-04-08 23:59:38,237: WARNING/MainProcess] /usr/local/lib/python3.12/site-packages/celery/worker/consumer/consumer.py:507: CPendingDeprecationWarning: The broker_connection_retry configuration setting will no longer determine
whether broker connection retries are made during startup in Celery 6.0 and above.
If you wish to retain the existing behavior for retrying connections on startup,
you should set broker_connection_retry_on_startup to True.
  warnings.warn(

[2024-04-08 23:59:38,260: INFO/MainProcess] Connected to redis://redis:6379/0
[2024-04-08 23:59:38,264: WARNING/MainProcess] /usr/local/lib/python3.12/site-packages/celery/worker/consumer/consumer.py:507: CPendingDeprecationWarning: The broker_connection_retry configuration setting will no longer determine
whether broker connection retries are made during startup in Celery 6.0 and above.
If you wish to retain the existing behavior for retrying connections on startup,
you should set broker_connection_retry_on_startup to True.
  warnings.warn(

[2024-04-08 23:59:38,278: INFO/MainProcess] mingle: searching for neighbors
[2024-04-08 23:59:39,303: INFO/MainProcess] mingle: all alone
[2024-04-08 23:59:39,337: INFO/MainProcess] celery@8a0a84fa708c ready.
[2024-04-09 21:16:36,698: WARNING/MainProcess] /usr/local/lib/python3.12/site-packages/celery/worker/consumer/consumer.py:507: CPendingDeprecationWarning: The broker_connection_retry configuration setting will no longer determine
whether broker connection retries are made during startup in Celery 6.0 and above.
If you wish to retain the existing behavior for retrying connections on startup,
you should set broker_connection_retry_on_startup to True.
  warnings.warn(

[2024-04-09 21:16:41,710: ERROR/MainProcess] consumer: Cannot connect to redis://redis:6379/0: Error -3 connecting to redis:6379. Try again..
Trying again in 2.00 seconds... (1/100)

[2024-04-09 21:16:48,723: ERROR/MainProcess] consumer: Cannot connect to redis://redis:6379/0: Error -3 connecting to redis:6379. Try again..
Trying again in 4.00 seconds... (2/100)

[2024-04-09 21:16:57,732: ERROR/MainProcess] consumer: Cannot connect to redis://redis:6379/0: Error -3 connecting to redis:6379. Try again..
Trying again in 6.00 seconds... (3/100)

[2024-04-09 21:17:08,743: ERROR/MainProcess] consumer: Cannot connect to redis://redis:6379/0: Error -3 connecting to redis:6379. Try again..
Trying again in 8.00 seconds... (4/100)

[2024-04-09 21:17:21,755: ERROR/MainProcess] consumer: Cannot connect to redis://redis:6379/0: Error -3 connecting to redis:6379. Try again..
Trying again in 10.00 seconds... (5/100)

[2024-04-09 21:17:36,765: ERROR/MainProcess] consumer: Cannot connect to redis://redis:6379/0: Error -3 connecting to redis:6379. Try again..
Trying again in 12.00 seconds... (6/100)

[2024-04-09 21:17:53,778: ERROR/MainProcess] consumer: Cannot connect to redis://redis:6379/0: Error -3 connecting to redis:6379. Try again..
Trying again in 14.00 seconds... (7/100)

[2024-04-09 21:18:12,792: ERROR/MainProcess] consumer: Cannot connect to redis://redis:6379/0: Error -3 connecting to redis:6379. Try again..
Trying again in 16.00 seconds... (8/100)

[2024-04-09 21:18:33,805: ERROR/MainProcess] consumer: Cannot connect to redis://redis:6379/0: Error -3 connecting to redis:6379. Try again..
Trying again in 18.00 seconds... (9/100)

[2024-04-09 21:18:56,816: ERROR/MainProcess] consumer: Cannot connect to redis://redis:6379/0: Error -3 connecting to redis:6379. Try again..
Trying again in 20.00 seconds... (10/100)

[2024-04-09 21:25:00,592: WARNING/MainProcess] /usr/local/lib/python3.12/site-packages/celery/worker/consumer/consumer.py:507: CPendingDeprecationWarning: The broker_connection_retry configuration setting will no longer determine
whether broker connection retries are made during startup in Celery 6.0 and above.
If you wish to retain the existing behavior for retrying connections on startup,
you should set broker_connection_retry_on_startup to True.
  warnings.warn(

[2024-04-09 21:25:00,617: INFO/MainProcess] Connected to redis://redis:6379/0
[2024-04-09 21:25:00,624: WARNING/MainProcess] /usr/local/lib/python3.12/site-packages/celery/worker/consumer/consumer.py:507: CPendingDeprecationWarning: The broker_connection_retry configuration setting will no longer determine
whether broker connection retries are made during startup in Celery 6.0 and above.
If you wish to retain the existing behavior for retrying connections on startup,
you should set broker_connection_retry_on_startup to True.
  warnings.warn(

[2024-04-09 21:25:00,634: INFO/MainProcess] mingle: searching for neighbors
[2024-04-09 21:25:01,668: INFO/MainProcess] mingle: all alone
[2024-04-09 21:25:01,711: INFO/MainProcess] celery@cf0fbb82771f ready.
[2024-04-09 21:25:01,723: INFO/MainProcess] Task women.tasks.dbackup_task[de683654-cc44-49d5-9007-27356e7127ed] received
[2024-04-09 21:25:01,903: WARNING/ForkPoolWorker-7] Waiting for database dump...
[2024-04-09 21:25:02,891: WARNING/ForkPoolWorker-7] Database successfully backed up
[2024-04-09 21:25:02,896: INFO/ForkPoolWorker-7] Task women.tasks.dbackup_task[de683654-cc44-49d5-9007-27356e7127ed] succeeded in 1.168355322000025s: None
[2024-04-09 21:58:55,485: INFO/MainProcess] Task women.tasks.send_activate_email_message_task[6f0bc5bb-0f49-4156-841c-3a7b5c4c7509] received
[2024-04-09 21:58:55,662: ERROR/ForkPoolWorker-7] Task women.tasks.send_activate_email_message_task[6f0bc5bb-0f49-4156-841c-3a7b5c4c7509] raised unexpected: Http404('No User matches the given query.')
Traceback (most recent call last):
  File "/usr/local/lib/python3.12/site-packages/django/shortcuts.py", line 85, in get_object_or_404
    return queryset.get(*args, **kwargs)
           ^^^^^^^^^^^^^^^^^^^^^^^^^^^^^
  File "/usr/local/lib/python3.12/site-packages/django/db/models/query.py", line 637, in get
    raise self.model.DoesNotExist(
users.models.User.DoesNotExist: User matching query does not exist.

During handling of the above exception, another exception occurred:

Traceback (most recent call last):
  File "/usr/local/lib/python3.12/site-packages/celery/app/trace.py", line 477, in trace_task
    R = retval = fun(*args, **kwargs)
                 ^^^^^^^^^^^^^^^^^^^^
  File "/usr/local/lib/python3.12/site-packages/celery/app/trace.py", line 760, in __protected_call__
    return self.run(*args, **kwargs)
           ^^^^^^^^^^^^^^^^^^^^^^^^^
  File "/app/women/tasks.py", line 13, in send_activate_email_message_task
    return send_activate_email_message(user_id)
           ^^^^^^^^^^^^^^^^^^^^^^^^^^^^^^^^^^^^
  File "/app/women/email.py", line 26, in send_activate_email_message
    user = get_object_or_404(get_user_model(), id=user_id)
           ^^^^^^^^^^^^^^^^^^^^^^^^^^^^^^^^^^^^^^^^^^^^^^^
  File "/usr/local/lib/python3.12/site-packages/django/shortcuts.py", line 87, in get_object_or_404
    raise Http404(
django.http.response.Http404: No User matches the given query.
[2024-04-09 22:01:00,481: INFO/MainProcess] Task women.tasks.send_activate_email_message_task[31f0ec3a-4a46-4e7a-bbe5-7bf2c85edf91] received
[2024-04-09 22:01:00,533: ERROR/ForkPoolWorker-7] Task women.tasks.send_activate_email_message_task[31f0ec3a-4a46-4e7a-bbe5-7bf2c85edf91] raised unexpected: Http404('No User matches the given query.')
Traceback (most recent call last):
  File "/usr/local/lib/python3.12/site-packages/django/shortcuts.py", line 85, in get_object_or_404
    return queryset.get(*args, **kwargs)
           ^^^^^^^^^^^^^^^^^^^^^^^^^^^^^
  File "/usr/local/lib/python3.12/site-packages/django/db/models/query.py", line 637, in get
    raise self.model.DoesNotExist(
users.models.User.DoesNotExist: User matching query does not exist.

During handling of the above exception, another exception occurred:

Traceback (most recent call last):
  File "/usr/local/lib/python3.12/site-packages/celery/app/trace.py", line 477, in trace_task
    R = retval = fun(*args, **kwargs)
                 ^^^^^^^^^^^^^^^^^^^^
  File "/usr/local/lib/python3.12/site-packages/celery/app/trace.py", line 760, in __protected_call__
    return self.run(*args, **kwargs)
           ^^^^^^^^^^^^^^^^^^^^^^^^^
  File "/app/women/tasks.py", line 13, in send_activate_email_message_task
    return send_activate_email_message(user_id)
           ^^^^^^^^^^^^^^^^^^^^^^^^^^^^^^^^^^^^
  File "/app/women/email.py", line 26, in send_activate_email_message
    user = get_object_or_404(get_user_model(), id=user_id)
           ^^^^^^^^^^^^^^^^^^^^^^^^^^^^^^^^^^^^^^^^^^^^^^^
  File "/usr/local/lib/python3.12/site-packages/django/shortcuts.py", line 87, in get_object_or_404
    raise Http404(
django.http.response.Http404: No User matches the given query.
[2024-04-09 22:08:57,130: INFO/MainProcess] Task women.tasks.send_activate_email_message_task[4160abb6-4bee-42c2-9c1f-e4e536a750cf] received
[2024-04-09 22:08:57,202: ERROR/ForkPoolWorker-7] Task women.tasks.send_activate_email_message_task[4160abb6-4bee-42c2-9c1f-e4e536a750cf] raised unexpected: Http404('No User matches the given query.')
Traceback (most recent call last):
  File "/usr/local/lib/python3.12/site-packages/django/shortcuts.py", line 85, in get_object_or_404
    return queryset.get(*args, **kwargs)
           ^^^^^^^^^^^^^^^^^^^^^^^^^^^^^
  File "/usr/local/lib/python3.12/site-packages/django/db/models/query.py", line 637, in get
    raise self.model.DoesNotExist(
users.models.User.DoesNotExist: User matching query does not exist.

During handling of the above exception, another exception occurred:

Traceback (most recent call last):
  File "/usr/local/lib/python3.12/site-packages/celery/app/trace.py", line 477, in trace_task
    R = retval = fun(*args, **kwargs)
                 ^^^^^^^^^^^^^^^^^^^^
  File "/usr/local/lib/python3.12/site-packages/celery/app/trace.py", line 760, in __protected_call__
    return self.run(*args, **kwargs)
           ^^^^^^^^^^^^^^^^^^^^^^^^^
  File "/app/women/tasks.py", line 13, in send_activate_email_message_task
    return send_activate_email_message(user_id)
           ^^^^^^^^^^^^^^^^^^^^^^^^^^^^^^^^^^^^
  File "/app/women/email.py", line 26, in send_activate_email_message
    user = get_object_or_404(get_user_model(), id=user_id)
           ^^^^^^^^^^^^^^^^^^^^^^^^^^^^^^^^^^^^^^^^^^^^^^^
  File "/usr/local/lib/python3.12/site-packages/django/shortcuts.py", line 87, in get_object_or_404
    raise Http404(
django.http.response.Http404: No User matches the given query.
[2024-04-09 22:12:54,783: INFO/MainProcess] Task women.tasks.send_activate_email_message_task[2a447845-ad08-4b2c-9c20-8fb5eb8da4c1] received
[2024-04-09 22:12:55,906: INFO/ForkPoolWorker-7] Task women.tasks.send_activate_email_message_task[2a447845-ad08-4b2c-9c20-8fb5eb8da4c1] succeeded in 1.1164972579999812s: None
[2024-04-09 22:17:15,021: INFO/MainProcess] Task women.tasks.send_activate_email_message_task[7f7f0d53-caf4-4af5-b476-4cfe39a81cb8] received
[2024-04-09 22:17:15,075: ERROR/ForkPoolWorker-7] Task women.tasks.send_activate_email_message_task[7f7f0d53-caf4-4af5-b476-4cfe39a81cb8] raised unexpected: Http404('No User matches the given query.')
Traceback (most recent call last):
  File "/usr/local/lib/python3.12/site-packages/django/shortcuts.py", line 85, in get_object_or_404
    return queryset.get(*args, **kwargs)
           ^^^^^^^^^^^^^^^^^^^^^^^^^^^^^
  File "/usr/local/lib/python3.12/site-packages/django/db/models/query.py", line 637, in get
    raise self.model.DoesNotExist(
users.models.User.DoesNotExist: User matching query does not exist.

During handling of the above exception, another exception occurred:

Traceback (most recent call last):
  File "/usr/local/lib/python3.12/site-packages/celery/app/trace.py", line 477, in trace_task
    R = retval = fun(*args, **kwargs)
                 ^^^^^^^^^^^^^^^^^^^^
  File "/usr/local/lib/python3.12/site-packages/celery/app/trace.py", line 760, in __protected_call__
    return self.run(*args, **kwargs)
           ^^^^^^^^^^^^^^^^^^^^^^^^^
  File "/app/women/tasks.py", line 13, in send_activate_email_message_task
    return send_activate_email_message(user_id)
           ^^^^^^^^^^^^^^^^^^^^^^^^^^^^^^^^^^^^
  File "/app/women/email.py", line 26, in send_activate_email_message
    user = get_object_or_404(get_user_model(), id=user_id)
           ^^^^^^^^^^^^^^^^^^^^^^^^^^^^^^^^^^^^^^^^^^^^^^^
  File "/usr/local/lib/python3.12/site-packages/django/shortcuts.py", line 87, in get_object_or_404
    raise Http404(
django.http.response.Http404: No User matches the given query.
[2024-04-09 22:17:49,149: INFO/MainProcess] Task women.tasks.send_activate_email_message_task[164b188e-407e-46a5-978c-e4c16e254973] received
[2024-04-09 22:17:49,202: ERROR/ForkPoolWorker-7] Task women.tasks.send_activate_email_message_task[164b188e-407e-46a5-978c-e4c16e254973] raised unexpected: Http404('No User matches the given query.')
Traceback (most recent call last):
  File "/usr/local/lib/python3.12/site-packages/django/shortcuts.py", line 85, in get_object_or_404
    return queryset.get(*args, **kwargs)
           ^^^^^^^^^^^^^^^^^^^^^^^^^^^^^
  File "/usr/local/lib/python3.12/site-packages/django/db/models/query.py", line 637, in get
    raise self.model.DoesNotExist(
users.models.User.DoesNotExist: User matching query does not exist.

During handling of the above exception, another exception occurred:

Traceback (most recent call last):
  File "/usr/local/lib/python3.12/site-packages/celery/app/trace.py", line 477, in trace_task
    R = retval = fun(*args, **kwargs)
                 ^^^^^^^^^^^^^^^^^^^^
  File "/usr/local/lib/python3.12/site-packages/celery/app/trace.py", line 760, in __protected_call__
    return self.run(*args, **kwargs)
           ^^^^^^^^^^^^^^^^^^^^^^^^^
  File "/app/women/tasks.py", line 13, in send_activate_email_message_task
    return send_activate_email_message(user_id)
           ^^^^^^^^^^^^^^^^^^^^^^^^^^^^^^^^^^^^
  File "/app/women/email.py", line 26, in send_activate_email_message
    user = get_object_or_404(get_user_model(), id=user_id)
           ^^^^^^^^^^^^^^^^^^^^^^^^^^^^^^^^^^^^^^^^^^^^^^^
  File "/usr/local/lib/python3.12/site-packages/django/shortcuts.py", line 87, in get_object_or_404
    raise Http404(
django.http.response.Http404: No User matches the given query.
[2024-04-09 22:18:47,317: INFO/MainProcess] Task women.tasks.send_activate_email_message_task[d940c616-877c-4144-9e9a-681d3cb057aa] received
[2024-04-09 22:18:47,370: ERROR/ForkPoolWorker-7] Task women.tasks.send_activate_email_message_task[d940c616-877c-4144-9e9a-681d3cb057aa] raised unexpected: Http404('No User matches the given query.')
Traceback (most recent call last):
  File "/usr/local/lib/python3.12/site-packages/django/shortcuts.py", line 85, in get_object_or_404
    return queryset.get(*args, **kwargs)
           ^^^^^^^^^^^^^^^^^^^^^^^^^^^^^
  File "/usr/local/lib/python3.12/site-packages/django/db/models/query.py", line 637, in get
    raise self.model.DoesNotExist(
users.models.User.DoesNotExist: User matching query does not exist.

During handling of the above exception, another exception occurred:

Traceback (most recent call last):
  File "/usr/local/lib/python3.12/site-packages/celery/app/trace.py", line 477, in trace_task
    R = retval = fun(*args, **kwargs)
                 ^^^^^^^^^^^^^^^^^^^^
  File "/usr/local/lib/python3.12/site-packages/celery/app/trace.py", line 760, in __protected_call__
    return self.run(*args, **kwargs)
           ^^^^^^^^^^^^^^^^^^^^^^^^^
  File "/app/women/tasks.py", line 13, in send_activate_email_message_task
    return send_activate_email_message(user_id)
           ^^^^^^^^^^^^^^^^^^^^^^^^^^^^^^^^^^^^
  File "/app/women/email.py", line 26, in send_activate_email_message
    user = get_object_or_404(get_user_model(), id=user_id)
           ^^^^^^^^^^^^^^^^^^^^^^^^^^^^^^^^^^^^^^^^^^^^^^^
  File "/usr/local/lib/python3.12/site-packages/django/shortcuts.py", line 87, in get_object_or_404
    raise Http404(
django.http.response.Http404: No User matches the given query.
[2024-04-09 22:20:15,967: INFO/MainProcess] Task women.tasks.send_activate_email_message_task[375c4ed0-5bf6-4191-badd-ce6b38e0b251] received
[2024-04-09 22:20:16,021: ERROR/ForkPoolWorker-7] Task women.tasks.send_activate_email_message_task[375c4ed0-5bf6-4191-badd-ce6b38e0b251] raised unexpected: Http404('No User matches the given query.')
Traceback (most recent call last):
  File "/usr/local/lib/python3.12/site-packages/django/shortcuts.py", line 85, in get_object_or_404
    return queryset.get(*args, **kwargs)
           ^^^^^^^^^^^^^^^^^^^^^^^^^^^^^
  File "/usr/local/lib/python3.12/site-packages/django/db/models/query.py", line 637, in get
    raise self.model.DoesNotExist(
users.models.User.DoesNotExist: User matching query does not exist.

During handling of the above exception, another exception occurred:

Traceback (most recent call last):
  File "/usr/local/lib/python3.12/site-packages/celery/app/trace.py", line 477, in trace_task
    R = retval = fun(*args, **kwargs)
                 ^^^^^^^^^^^^^^^^^^^^
  File "/usr/local/lib/python3.12/site-packages/celery/app/trace.py", line 760, in __protected_call__
    return self.run(*args, **kwargs)
           ^^^^^^^^^^^^^^^^^^^^^^^^^
  File "/app/women/tasks.py", line 13, in send_activate_email_message_task
    return send_activate_email_message(user_id)
           ^^^^^^^^^^^^^^^^^^^^^^^^^^^^^^^^^^^^
  File "/app/women/email.py", line 26, in send_activate_email_message
    user = get_object_or_404(get_user_model(), id=user_id)
           ^^^^^^^^^^^^^^^^^^^^^^^^^^^^^^^^^^^^^^^^^^^^^^^
  File "/usr/local/lib/python3.12/site-packages/django/shortcuts.py", line 87, in get_object_or_404
    raise Http404(
django.http.response.Http404: No User matches the given query.
